Workbook

Sheet Instructions
A1: Logistic Regression Binary Classification Practice Worksheet
A3: ======================================================================
A5: [Learning Objectives]
A6: 1. Understand binary classification problem using Logistic Regression
A7: 2. Role and calculation of Sigmoid activation function
A8: 3. Understand Binary Cross-Entropy (BCE) loss function
A9: 4. Derive simplified gradient of BCE + Sigmoid
A10: 5. Update weights through backpropagation
A12: [Network Structure]
A13: • Input matrix X: 10 samples × 8 features (10×8 matrix)
A14: • Weight matrix W: 8 features × 1 output (8×1 vector)
A15: • Bias b: Scalar
A16: • Linear combination Z: Z = X · W + b
A17: • Activation function: Sigmoid → Y_pred = σ(Z) = 1/(1+e^(-Z))
... A61: 4. Hint: When calculating Sigmoid, first compute e^(-z), then 1/(1+e^(-z))

Sheet Forward_Propagation
A1: Forward Propagation - Logistic Regression
A3: Progress: | B3: =COUNTIF(F:F,"✓")/30*100&"%"
A5: === Input Matrix X (10×8) === | L5: === Weight W (8×1) === | O5: === Ground Truth Y_true ===
A6: Sample | B6: x1 | C6: x2 | D6: x3 | E6: x4 | F6: x5 | G6: x6 | H6: x7 | I6: x8 | O6: (0 or 1)
A7: s1 | B7: 1 | C7: 2 | D7: 0 | E7: -1 | F7: 1 | G7: 0 | H7: 0.5 | I7: -0.5 | L7: w1 | M7: 0.3 | O7: y1 | P7: 1
A8: s2 | B8: 0.5 | C8: 1 | D8: 1 | E8: 0 | F8: 0.5 | G8: -1 | H8: 0 | I8: 1 | L8: w2 | M8: 0.4 | O8: y2 | P8: 0
A9: s3 | B9: 2 | C9: 0 | D9: -1 | E9: 1 | F9: 0 | G9: 0.5 | H9: 1 | I9: 0 | L9: w3 | M9: -0.2 | O9: y3 | P9: 1
A10: s4 | B10: 0 | C10: 1.5 | D10: 0.5 | E10: 0.5 | F10: -0.5 | G10: 1 | H10: -1 | I10: 0.5 | L10: w4 | M10: 0.5 | O10: y4 | P10: 1
A11: s5 | B11: 1 | C11: -1 | D11: 2 | E11: 0 | F11: 1 | G11: 0 | H11: 0.5 | I11: 0 | L11: w5 | M11: -0.3 | O11: y5 | P11: 0
A12: s6 | B12: -0.5 | C12: 1 | D12: 0 | E12: 1.5 | F12: 0 | G12: 0.5 | H12: 0 | I12: 1 | L12: w6 | M12: 0.2 | O12: y6 | P12: 1
A13: s7 | B13: 1.5 | C13: 0.5 | D13: 1 | E13: -0.5 | F13: 0.5 | G13: 0 | H13: 1 | I13: -1 | L13: w7 | M13: 0.35 | O13: y7 | P13: 1
A14: s8 | B14: 0 | C14: 2 | D14: -0.5 | E14: 0 | F14: 1 | G14: -0.5 | H14: 0.5 | I14: 0.5 | L14: w8 | M14: -0.25 | O14: y8 | P14: 0
A15: s9 | B15: 1 | C15: 0 | D15: 1 | E15: 1 | F15: -1 | G15: 1 | H15: 0 | I15: 0 | O15: y9 | P15: 1
A16: s10 | B16: 0.5 | C16: 0.5 | D16: 0.5 | E16: 0.5 | F16: 0.5 | G16: 0.5 | H16: 0.5 | I16: 0.5 | L16: b | M16: -0.5 | O16: y10 | P16: 0
A20: === Step 1: Linear Combination Z = X · W + b ===
A21: Formula: z_i = Σ(x_ij × w_j) + b
A23: Sample | B23: Calculation formula | C23: z_i | D23: Student input | E23: Verification
A24: s1 | B24: 1.0×0.30 + 2.0×0.40 + 0.0×-0.20 + ... + (-0.5) | C24: 0.1 | E24: =IF(ABS(D24-Answer_Key!B3)<0.0001,"✓","✗")
A25: s2 | B25: 0.5×0.30 + 1.0×0.40 + 1.0×-0.20 + ... + (-0.5) | C25: -0.75 | E25: =IF(ABS(D25-Answer_Key!B4)<0.0001,"✓","✗")
A26: s3 | B26: 2.0×0.30 + 0.0×0.40 + -1.0×-0.20 + ... + (-0.5) | C26: 1.25 | E26: =IF(ABS(D26-Answer_Key!B5)<0.0001,"✓","✗")
A27: s4 | B27: 0.0×0.30 + 1.5×0.40 + 0.5×-0.20 + ... + (-0.5) | C27: 0.125 | E27: =IF(ABS(D27-Answer_Key!B6)<0.0001,"✓","✗")
A28: s5 | B28: 1.0×0.30 + -1.0×0.40 + 2.0×-0.20 + ... + (-0.5) | C28: -1.125 | E28: =IF(ABS(D28-Answer_Key!B7)<0.0001,"✓","✗")
A29: s6 | B29: -0.5×0.30 + 1.0×0.40 + 0.0×-0.20 + ... + (-0.5) | C29: 0.35 | E29: =IF(ABS(D29-Answer_Key!B8)<0.0001,"✓","✗")
A30: s7 | B30: 1.5×0.30 + 0.5×0.40 + 1.0×-0.20 + ... + (-0.5) | C30: 0.15 | E30: =IF(ABS(D30-Answer_Key!B9)<0.0001,"✓","✗")
A31: s8 | B31: 0.0×0.30 + 2.0×0.40 + -0.5×-0.20 + ... + (-0.5) | C31: 0.05 | E31: =IF(ABS(D31-Answer_Key!B10)<0.0001,"✓","✗")
A32: s9 | B32: 1.0×0.30 + 0.0×0.40 + 1.0×-0.20 + ... + (-0.5) | C32: 0.6 | E32: =IF(ABS(D32-Answer_Key!B11)<0.0001,"✓","✗")
A33: s10 | B33: 0.5×0.30 + 0.5×0.40 + 0.5×-0.20 + ... + (-0.5) | C33: 0 | E33: =IF(ABS(D33-Answer_Key!B12)<0.0001,"✓","✗")
A36: === Step 2: Sigmoid Activation σ(z) = 1/(1+e^(-z)) ===
A37: Hint: First calculate e^(-z), then calculate 1/(1+e^(-z))
A39: Sample | B39: z_i | C39: e^(-z) | D39: σ(z) = y_pred | E39: Student input | F39: Verification
A40: s1 | B40: 0.1 | C40: 0.9048 | D40: 0.525 | F40: =IF(ABS(E40-Answer_Key!C3)<0.0001,"✓","✗")
A41: s2 | B41: -0.75 | C41: 2.117 | D41: 0.3208 | F41: =IF(ABS(E41-Answer_Key!C4)<0.0001,"✓","✗")
A42: s3 | B42: 1.25 | C42: 0.2865 | D42: 0.7773 | F42: =IF(ABS(E42-Answer_Key!C5)<0.0001,"✓","✗")
A43: s4 | B43: 0.125 | C43: 0.8825 | D43: 0.5312 | F43: =IF(ABS(E43-Answer_Key!C6)<0.0001,"✓","✗")
A44: s5 | B44: -1.125 | C44: 3.0802 | D44: 0.2451 | F44: =IF(ABS(E44-Answer_Key!C7)<0.0001,"✓","✗")
A45: s6 | B45: 0.35 | C45: 0.7047 | D45: 0.5866 | F45: =IF(ABS(E45-Answer_Key!C8)<0.0001,"✓","✗")
A46: s7 | B46: 0.15 | C46: 0.8607 | D46: 0.5374 | F46: =IF(ABS(E46-Answer_Key!C9)<0.0001,"✓","✗")
A47: s8 | B47: 0.05 | C47: 0.9512 | D47: 0.5125 | F47: =IF(ABS(E47-Answer_Key!C10)<0.0001,"✓","✗")
A48: s9 | B48: 0.6 | C48: 0.5488 | D48: 0.6457 | F48: =IF(ABS(E48-Answer_Key!C11)<0.0001,"✓","✗")
A49: s10 | B49: 0 | C49: 1 | D49: 0.5 | F49: =IF(ABS(E49-Answer_Key!C12)<0.0001,"✓","✗")
...

Sheet Backward_Propagation
A1: Backward Propagation - Logistic Regression
A3: ★ Key: BCE + Sigmoid gradient = (y_pred - y_true) / n
A5: Progress: | B5: =COUNTIF(E:E,"✓")/20*100&"%"
A7: Learning rate (lr): | B7: 0.1
A9: === Step 1: Output Gradient ∂L/∂Z ===
A10: Formula: ∂L/∂z_i = (1/n) × (y_pred_i - y_true_i)
A11: ※ BCE + Sigmoid combination gradient simplifies nicely!
A13: Sample | B13: y_pred - y_true | C13: ∂L/∂z | D13: Student input | E13: Verification
A14: s1 | B14: 0.5250 - 1 = -0.4750 | C14: -0.047502 | E14: =IF(ABS(D14-Answer_Key!B23)<0.0001,"✓","✗")
A15: s2 | B15: 0.3208 - 0 = 0.3208 | C15: 0.032082 | E15: =IF(ABS(D15-Answer_Key!B24)<0.0001,"✓","✗")
A16: s3 | B16: 0.7773 - 1 = -0.2227 | C16: -0.02227 | E16: =IF(ABS(D16-Answer_Key!B25)<0.0001,"✓","✗")
A17: s4 | B17: 0.5312 - 1 = -0.4688 | C17: -0.046879 | E17: =IF(ABS(D17-Answer_Key!B26)<0.0001,"✓","✗")
A18: s5 | B18: 0.2451 - 0 = 0.2451 | C18: 0.024509 | E18: =IF(ABS(D18-Answer_Key!B27)<0.0001,"✓","✗")
A19: s6 | B19: 0.5866 - 1 = -0.4134 | C19: -0.041338 | E19: =IF(ABS(D19-Answer_Key!B28)<0.0001,"✓","✗")
A20: s7 | B20: 0.5374 - 1 = -0.4626 | C20: -0.046257 | E20: =IF(ABS(D20-Answer_Key!B29)<0.0001,"✓","✗")
A21: s8 | B21: 0.5125 - 0 = 0.5125 | C21: 0.05125 | E21: =IF(ABS(D21-Answer_Key!B30)<0.0001,"✓","✗")
A22: s9 | B22: 0.6457 - 1 = -0.3543 | C22: -0.035434 | E22: =IF(ABS(D22-Answer_Key!B31)<0.0001,"✓","✗")
A23: s10 | B23: 0.5000 - 0 = 0.5000 | C23: 0.05 | E23: =IF(ABS(D23-Answer_Key!B32)<0.0001,"✓","✗")
A26: === Step 2: Weight Gradient ∂L/∂W ===
A27: Formula: ∂L/∂W = X^T · ∂L/∂Z
A28: Each weight: ∂L/∂w_j = Σ_i (x_ij × ∂L/∂z_i)
A30: Weight | B30: Calculation (column j of X · ∂L/∂Z) | C30: ∂L/∂w | D30: Student input | E30: Verification
A31: ∂L/∂w1 | B31: 1.0×-0.0475 + 0.5×0.0321 + ... | C31: -0.110643 | E31: =IF(ABS(D31-Answer_Key!B35)<0.0001,"✓","✗")
A32: ∂L/∂w2 | B32: 2.0×-0.0475 + 1.0×0.0321 + ... | C32: -0.094716 | E32: =IF(ABS(D32-Answer_Key!B36)<0.0001,"✓","✗")
A33: ∂L/∂w3 | B33: 0.0×-0.0475 + 1.0×0.0321 + ... | C33: -0.002387 | E33: =IF(ABS(D33-Answer_Key!B37)<0.0001,"✓","✗")
A34: ∂L/∂w4 | B34: -1.0×-0.0475 + 0.0×0.0321 + ... | C34: -0.047521 | E34: =IF(ABS(D34-Answer_Key!B38)<0.0001,"✓","✗")
A35: ∂L/∂w5 | B35: 1.0×-0.0475 + 0.5×0.0321 + ... | C35: 0.105043 | E35: =IF(ABS(D35-Answer_Key!B39)<0.0001,"✓","✗")
A36: ∂L/∂w6 | B36: 0.0×-0.0475 + -1.0×0.0321 + ... | C36: -0.146825 | E36: =IF(ABS(D36-Answer_Key!B40)<0.0001,"✓","✗")
A37: ∂L/∂w7 | B37: 0.5×-0.0475 + 0.0×0.0321 + ... | C37: 0.01748 | E37: =IF(ABS(D37-Answer_Key!B41)<0.0001,"✓","✗")
A38: ∂L/∂w8 | B38: -0.5×-0.0475 + 1.0×0.0321 + ... | C38: 0.087937 | E38: =IF(ABS(D38-Answer_Key!B42)<0.0001,"✓","✗")
A40: ∂L/∂b | B40: Σ(∂L/∂z_i) | C40: -0.08184 | E40: =IF(ABS(D40-Answer_Key!B43)<0.0001,"✓","✗")
A42: === Step 3: Weight Update ===
A43: Formula: w_new = w_old - lr × ∂L/∂w (lr = 0.1)
A45: Weight | B45: Existing value | C45: Gradient | D45: New value | E45: Student input | F45: Verification
A46: w1 | B46: 0.3 | C46: -0.110643 | D46: 0.311064 | F46: =IF(ABS(E46-Answer_Key!B46)<0.0001,"✓","✗")
A47: w2 | B47: 0.4 | C47: -0.094716 | D47: 0.409472 | F47: =IF(ABS(E47-Answer_Key!B47)<0.0001,"✓","✗")
A48: w3 | B48: -0.2 | C48: -0.002387 | D48: -0.199761 | F48: =IF(ABS(E48-Answer_Key!B48)<0.0001,"✓","✗")
A49: w4 | B49: 0.5 | C49: -0.047521 | D49: 0.504752 | F49: =IF(ABS(E49-Answer_Key!B49)<0.0001,"✓","✗")
A50: w5 | B50: -0.3 | C50: 0.105043 | D50: -0.310504 | F50: =IF(ABS(E50-Answer_Key!B50)<0.0001,"✓","✗")
A51: w6 | B51: 0.2 | C51: -0.146825 | D51: 0.214682 | F51: =IF(ABS(E51-Answer_Key!B51)<0.0001,"✓","✗")
...

Sheet Answer_Key
A1: Answer Key - Logistic Regression
A3: === Forward === | B3: z_i | C3: y_pred_i | D3: BCE_i
A4: Sample 1 | B4: 0.1 | C4: 0.524979 | D4: 0.644396
A5: Sample 2 | B5: -0.75 | C5: 0.320821 | D5: 0.386871
A6: Sample 3 | B6: 1.25 | C6: 0.7773 | D6: 0.251929
A7: Sample 4 | B7: 0.125 | C7: 0.531209 | D7: 0.632599
A8: Sample 5 | B8: -1.125 | C8: 0.245085 | D8: 0.28115
A9: Sample 6 | B9: 0.35 | C9: 0.586618 | D9: 0.533382
A10: Sample 7 | B10: 0.15 | C10: 0.53743 | D10: 0.620957
A11: Sample 8 | B11: 0.05 | C11: 0.512497 | D11: 0.718459
A12: Sample 9 | B12: 0.6 | C12: 0.645656 | D12: 0.437488
A13: Sample 10 | B13: 0 | C13: 0.5 | D13: 0.693147
A15: Σ(BCE_i) | B15: 5.200378
A17: Loss (Average BCE) | B17: 0.520038
A19: === Backward ===
A21: n (sample count) | B21: 10
A22: ∂L/∂Z:
A23: ∂L/∂z_1 | B23: -0.047502
A24: ∂L/∂z_2 | B24: 0.032082
A25: ∂L/∂z_3 | B25: -0.02227
A26: ∂L/∂z_4 | B26: -0.046879
A27: ∂L/∂z_5 | B27: 0.024509
A28: ∂L/∂z_6 | B28: -0.041338
A29: ∂L/∂z_7 | B29: -0.046257
A30: ∂L/∂z_8 | B30: 0.05125
A31: ∂L/∂z_9 | B31: -0.035434
A32: ∂L/∂z_10 | B32: 0.05
A34: ∂L/∂W:
A35: ∂L/∂w1 | B35: -0.110643
A36: ∂L/∂w2 | B36: -0.094716
A37: ∂L/∂w3 | B37: -0.002387
A38: ∂L/∂w4 | B38: -0.047521
A39: ∂L/∂w5 | B39: 0.105043
A40: ∂L/∂w6 | B40: -0.146825
A41: ∂L/∂w7 | B41: 0.01748
A42: ∂L/∂w8 | B42: 0.087937
A43: ∂L/∂b | B43: -0.08184
A45: === Updated Weights ===
A46: w1_new | B46: 0.311064
A47: w2_new | B47: 0.409472
...
