Workbook

Sheet Instructions
A1: Linear Regression Matrix Operations Practice Worksheet
A3: ======================================================================
A5: [Learning Objectives]
A6: 1. Understand linear regression using matrix form input data and weights
A7: 2. Calculate forward propagation through Matrix Multiplication
A8: 3. Calculate MSE loss function gradient (matrix differentiation)
A9: 4. Update weight matrix through backpropagation
A11: [Network Structure]
A12: • Input matrix X: 10 samples × 8 features (10×8 matrix)
A13: • Weight matrix W: 8 features × 1 output (8×1 vector)
A14: • Bias b: Scalar (applied equally to all samples)
A15: • Output Y_pred: 10 samples × 1 output (10×1 vector)
A16: • Loss function: MSE (Mean Squared Error)
A18: [Mathematical Expression]
... A39: 4. Hint: Matrix multiplication is calculated in 'row × column' order

Sheet Forward_Propagation
A1: Forward Propagation - Matrix Operations
A3: Progress: | B3: =COUNTIF(Q:Q,"✓")/12*100&"%"
A5: === Input Matrix X (10×8) === | L5: === Weight W (8×1) === | O5: === Ground Truth Y_true ===
A6: Sample | B6: x1 | C6: x2 | D6: x3 | E6: x4 | F6: x5 | G6: x6 | H6: x7 | I6: x8
A7: s1 | B7: 1 | C7: 2 | D7: 0 | E7: -1 | F7: 1 | G7: 0 | H7: 0.5 | I7: -0.5 | L7: w1 | M7: 0.2 | O7: y1 | P7: 2
A8: s2 | B8: 0.5 | C8: 1 | D8: 1 | E8: 0 | F8: 0.5 | G8: -1 | H8: 0 | I8: 1 | L8: w2 | M8: 0.3 | O8: y2 | P8: 1.5
A9: s3 | B9: 2 | C9: 0 | D9: -1 | E9: 1 | F9: 0 | G9: 0.5 | H9: 1 | I9: 0 | L9: w3 | M9: -0.1 | O9: y3 | P9: 1
A10: s4 | B10: 0 | C10: 1.5 | D10: 0.5 | E10: 0.5 | F10: -0.5 | G10: 1 | H10: -1 | I10: 0.5 | L10: w4 | M10: 0.4 | O10: y4 | P10: 2.5
A11: s5 | B11: 1 | C11: -1 | D11: 2 | E11: 0 | F11: 1 | G11: 0 | H11: 0.5 | I11: 0 | L11: w5 | M11: -0.2 | O11: y5 | P11: 1.8
A12: s6 | B12: -0.5 | C12: 1 | D12: 0 | E12: 1.5 | F12: 0 | G12: 0.5 | H12: 0 | I12: 1 | L12: w6 | M12: 0.1 | O12: y6 | P12: 2.2
A13: s7 | B13: 1.5 | C13: 0.5 | D13: 1 | E13: -0.5 | F13: 0.5 | G13: 0 | H13: 1 | I13: -1 | L13: w7 | M13: 0.25 | O13: y7 | P13: 1.2
A14: s8 | B14: 0 | C14: 2 | D14: -0.5 | E14: 0 | F14: 1 | G14: -0.5 | H14: 0.5 | I14: 0.5 | L14: w8 | M14: -0.15 | O14: y8 | P14: 1.7
A15: s9 | B15: 1 | C15: 0 | D15: 1 | E15: 1 | F15: -1 | G15: 1 | H15: 0 | I15: 0 | O15: y9 | P15: 1.4
A16: s10 | B16: 0.5 | C16: 0.5 | D16: 0.5 | E16: 0.5 | F16: 0.5 | G16: 0.5 | H16: 0.5 | I16: 0.5 | L16: b | M16: 0.5 | O16: y10 | P16: 2
A20: === Step 1: Matrix Multiplication (X · W) - Calculation per Sample ===
A21: Formula: z_i = x_i1×w1 + x_i2×w2 + ... + x_i8×w8
A23: Sample | B23: Formula (product of each term) | J23: Total (z) | K23: Student input | L23: Verification
A24: s1 | B24: 1.0×0.20 + 2.0×0.30 + 0.0×-0.10 + -1.0×0.40 + ... | J24: 0.9 | L24: =IF(ABS(K24-Answer_Key!C3)<0.0001,"✓","✗")
A25: s2 | B25: 0.5×0.20 + 1.0×0.30 + 1.0×-0.10 + 0.0×0.40 + ... | J25: 0.45 | L25: =IF(ABS(K25-Answer_Key!C4)<0.0001,"✓","✗")
A26: s3 | B26: 2.0×0.20 + 0.0×0.30 + -1.0×-0.10 + 1.0×0.40 + ... | J26: 1.7 | L26: =IF(ABS(K26-Answer_Key!C5)<0.0001,"✓","✗")
A27: s4 | B27: 0.0×0.20 + 1.5×0.30 + 0.5×-0.10 + 0.5×0.40 + ... | J27: 0.975 | L27: =IF(ABS(K27-Answer_Key!C6)<0.0001,"✓","✗")
A28: s5 | B28: 1.0×0.20 + -1.0×0.30 + 2.0×-0.10 + 0.0×0.40 + ... | J28: 0.125 | L28: =IF(ABS(K28-Answer_Key!C7)<0.0001,"✓","✗")
A29: s6 | B29: -0.5×0.20 + 1.0×0.30 + 0.0×-0.10 + 1.5×0.40 + ... | J29: 1.2 | L29: =IF(ABS(K29-Answer_Key!C8)<0.0001,"✓","✗")
A30: s7 | B30: 1.5×0.20 + 0.5×0.30 + 1.0×-0.10 + -0.5×0.40 + ... | J30: 0.95 | L30: =IF(ABS(K30-Answer_Key!C9)<0.0001,"✓","✗")
A31: s8 | B31: 0.0×0.20 + 2.0×0.30 + -0.5×-0.10 + 0.0×0.40 + ... | J31: 0.95 | L31: =IF(ABS(K31-Answer_Key!C10)<0.0001,"✓","✗")
A32: s9 | B32: 1.0×0.20 + 0.0×0.30 + 1.0×-0.10 + 1.0×0.40 + ... | J32: 1.3 | L32: =IF(ABS(K32-Answer_Key!C11)<0.0001,"✓","✗")
A33: s10 | B33: 0.5×0.20 + 0.5×0.30 + 0.5×-0.10 + 0.5×0.40 + ... | J33: 0.9 | L33: =IF(ABS(K33-Answer_Key!C12)<0.0001,"✓","✗")
A36: === Step 2: Add Bias (z + b) → Y_pred ===
A37: Formula: y_pred_i = z_i + b (b = 0.5)
A39: Sample | B39: z_i | C39: + b | D39: y_pred | E39: Student input | F39: Verification
A40: s1 | B40: 0.9 | C40: + 0.5 | D40: 0.9 | F40: =IF(ABS(E40-Answer_Key!D3)<0.0001,"✓","✗")
A41: s2 | B41: 0.45 | C41: + 0.5 | D41: 0.45 | F41: =IF(ABS(E41-Answer_Key!D4)<0.0001,"✓","✗")
A42: s3 | B42: 1.7 | C42: + 0.5 | D42: 1.7 | F42: =IF(ABS(E42-Answer_Key!D5)<0.0001,"✓","✗")
A43: s4 | B43: 0.975 | C43: + 0.5 | D43: 0.975 | F43: =IF(ABS(E43-Answer_Key!D6)<0.0001,"✓","✗")
A44: s5 | B44: 0.125 | C44: + 0.5 | D44: 0.125 | F44: =IF(ABS(E44-Answer_Key!D7)<0.0001,"✓","✗")
A45: s6 | B45: 1.2 | C45: + 0.5 | D45: 1.2 | F45: =IF(ABS(E45-Answer_Key!D8)<0.0001,"✓","✗")
A46: s7 | B46: 0.95 | C46: + 0.5 | D46: 0.95 | F46: =IF(ABS(E46-Answer_Key!D9)<0.0001,"✓","✗")
A47: s8 | B47: 0.95 | C47: + 0.5 | D47: 0.95 | F47: =IF(ABS(E47-Answer_Key!D10)<0.0001,"✓","✗")
A48: s9 | B48: 1.3 | C48: + 0.5 | D48: 1.3 | F48: =IF(ABS(E48-Answer_Key!D11)<0.0001,"✓","✗")
A49: s10 | B49: 0.9 | C49: + 0.5 | D49: 0.9 | F49: =IF(ABS(E49-Answer_Key!D12)<0.0001,"✓","✗")
...

Sheet Backward_Propagation
A1: Backward Propagation - Gradient Calculation
A3: Progress: | B3: =COUNTIF(E:E,"✓")/10*100&"%"
A5: Learning rate (lr): | B5: 0.01
A7: === Step 1: Output Gradient (∂L/∂Y_pred) ===
A8: Formula: ∂L/∂y_pred_i = (1/n) × (y_pred_i - y_true_i)
A10: Sample | B10: Calculation | C10: ∂L/∂y_pred | D10: Student input | E10: Verification
A11: s1 | B11: (1/10) × (0.9000 - 2.00) | C11: -0.11 | E11: =IF(ABS(D11-Answer_Key!B25)<0.0001,"✓","✗")
A12: s2 | B12: (1/10) × (0.4500 - 1.50) | C12: -0.105 | E12: =IF(ABS(D12-Answer_Key!B26)<0.0001,"✓","✗")
A13: s3 | B13: (1/10) × (1.7000 - 1.00) | C13: 0.07 | E13: =IF(ABS(D13-Answer_Key!B27)<0.0001,"✓","✗")
A14: s4 | B14: (1/10) × (0.9750 - 2.50) | C14: -0.1525 | E14: =IF(ABS(D14-Answer_Key!B28)<0.0001,"✓","✗")
A15: s5 | B15: (1/10) × (0.1250 - 1.80) | C15: -0.1675 | E15: =IF(ABS(D15-Answer_Key!B29)<0.0001,"✓","✗")
A16: s6 | B16: (1/10) × (1.2000 - 2.20) | C16: -0.1 | E16: =IF(ABS(D16-Answer_Key!B30)<0.0001,"✓","✗")
A17: s7 | B17: (1/10) × (0.9500 - 1.20) | C17: -0.025 | E17: =IF(ABS(D17-Answer_Key!B31)<0.0001,"✓","✗")
A18: s8 | B18: (1/10) × (0.9500 - 1.70) | C18: -0.075 | E18: =IF(ABS(D18-Answer_Key!B32)<0.0001,"✓","✗")
A19: s9 | B19: (1/10) × (1.3000 - 1.40) | C19: -0.01 | E19: =IF(ABS(D19-Answer_Key!B33)<0.0001,"✓","✗")
A20: s10 | B20: (1/10) × (0.9000 - 2.00) | C20: -0.11 | E20: =IF(ABS(D20-Answer_Key!B34)<0.0001,"✓","✗")
A23: === Step 2: Weight Gradient (∂L/∂W) ===
A24: Formula: ∂L/∂W = X^T · (∂L/∂Y_pred) = X^T · dL_dY
A25: Each weight: ∂L/∂w_j = Σ_i (x_ij × ∂L/∂y_pred_i)
A27: Weight | B27: Calculation (column j of X · dL_dY) | C27: ∂L/∂w | D27: Student input | E27: Verification
A28: ∂L/∂w1 | B28: 1.0×-0.1100 + 0.5×-0.1050 + 2.0×0.0700 + ... | C28: -0.2425 | E28: =IF(ABS(D28-Answer_Key!B37)<0.0001,"✓","✗")
A29: ∂L/∂w2 | B29: 2.0×-0.1100 + 1.0×-0.1050 + 0.0×0.0700 + ... | C29: -0.70375 | E29: =IF(ABS(D29-Answer_Key!B38)<0.0001,"✓","✗")
A30: ∂L/∂w3 | B30: 0.0×-0.1100 + 1.0×-0.1050 + -1.0×0.0700 + ... | C30: -0.63875 | E30: =IF(ABS(D30-Answer_Key!B39)<0.0001,"✓","✗")
A31: ∂L/∂w4 | B31: -1.0×-0.1100 + 0.0×-0.1050 + 1.0×0.0700 + ... | C31: -0.09875 | E31: =IF(ABS(D31-Answer_Key!B40)<0.0001,"✓","✗")
A32: ∂L/∂w5 | B32: 1.0×-0.1100 + 0.5×-0.1050 + 0.0×0.0700 + ... | C32: -0.38625 | E32: =IF(ABS(D32-Answer_Key!B41)<0.0001,"✓","✗")
A33: ∂L/∂w6 | B33: 0.0×-0.1100 + -1.0×-0.1050 + 0.5×0.0700 + ... | C33: -0.09 | E33: =IF(ABS(D33-Answer_Key!B42)<0.0001,"✓","✗")
A34: ∂L/∂w7 | B34: 0.5×-0.1100 + 0.0×-0.1050 + 1.0×0.0700 + ... | C34: -0.03375 | E34: =IF(ABS(D34-Answer_Key!B43)<0.0001,"✓","✗")
A35: ∂L/∂w8 | B35: -0.5×-0.1100 + 1.0×-0.1050 + 0.0×0.0700 + ... | C35: -0.29375 | E35: =IF(ABS(D35-Answer_Key!B44)<0.0001,"✓","✗")
A37: ∂L/∂b | B37: Σ(∂L/∂y_pred_i) = Sum of all gradients | C37: -0.785 | E37: =IF(ABS(D37-Answer_Key!B45)<0.0001,"✓","✗")
A39: === Step 3: Weight Update ===
A40: Formula: w_new = w_old - lr × ∂L/∂w (lr = 0.01)
A42: Weight | B42: Existing value | C42: Gradient | D42: New value | E42: Student input | F42: Verification
A43: w1 | B43: 0.2 | C43: -0.2425 | D43: 0.202425 | F43: =IF(ABS(E43-Answer_Key!B48)<0.0001,"✓","✗")
A44: w2 | B44: 0.3 | C44: -0.70375 | D44: 0.307037 | F44: =IF(ABS(E44-Answer_Key!B49)<0.0001,"✓","✗")
A45: w3 | B45: -0.1 | C45: -0.63875 | D45: -0.093613 | F45: =IF(ABS(E45-Answer_Key!B50)<0.0001,"✓","✗")
A46: w4 | B46: 0.4 | C46: -0.09875 | D46: 0.400987 | F46: =IF(ABS(E46-Answer_Key!B51)<0.0001,"✓","✗")
A47: w5 | B47: -0.2 | C47: -0.38625 | D47: -0.196138 | F47: =IF(ABS(E47-Answer_Key!B52)<0.0001,"✓","✗")
A48: w6 | B48: 0.1 | C48: -0.09 | D48: 0.1009 | F48: =IF(ABS(E48-Answer_Key!B53)<0.0001,"✓","✗")
A49: w7 | B49: 0.25 | C49: -0.03375 | D49: 0.250337 | F49: =IF(ABS(E49-Answer_Key!B54)<0.0001,"✓","✗")
A50: w8 | B50: -0.15 | C50: -0.29375 | D50: -0.147062 | F50: =IF(ABS(E50-Answer_Key!B55)<0.0001,"✓","✗")
...

Sheet Answer_Key
A1: Answer Key
A3: === Forward === | B3: z_i | C3: z_i | D3: y_pred_i
A4: Sample 1 | B4: 0.4 | C4: 0.9 | D4: 0.9
A5: Sample 2 | B5: -0.05 | C5: 0.45 | D5: 0.45
A6: Sample 3 | B6: 1.2 | C6: 1.7 | D6: 1.7
A7: Sample 4 | B7: 0.475 | C7: 0.975 | D7: 0.975
A8: Sample 5 | B8: -0.375 | C8: 0.125 | D8: 0.125
A9: Sample 6 | B9: 0.7 | C9: 1.2 | D9: 1.2
A10: Sample 7 | B10: 0.45 | C10: 0.95 | D10: 0.95
A11: Sample 8 | B11: 0.45 | C11: 0.95 | D11: 0.95
A12: Sample 9 | B12: 0.8 | C12: 1.3 | D12: 1.3
A13: Sample 10 | B13: 0.4 | C13: 0.9 | D13: 0.9
A15: === Error & Loss ===
A16: error_1 | B16: -1.1
A17: error_2 | B17: -1.05
A18: error_3 | B18: 0.7
A19: error_4 | B19: -1.525
A20: error_5 | B20: -1.675
A21: error_6 | B21: -1
A22: error_7 | B22: -0.25
A23: error_8 | B23: -0.75
A24: error_9 | B24: -0.1
A25: error_10 | B25: -1.1
A27: Loss (MSE) | B27: 0.538938
A29: === Backward ===
A31: ∂L/∂Y_pred:
A32: ∂L/∂y_pred_1 | B32: -0.11
A33: ∂L/∂y_pred_2 | B33: -0.105
A34: ∂L/∂y_pred_3 | B34: 0.07
A35: ∂L/∂y_pred_4 | B35: -0.1525
A36: ∂L/∂y_pred_5 | B36: -0.1675
A37: ∂L/∂y_pred_6 | B37: -0.1
A38: ∂L/∂y_pred_7 | B38: -0.025
A39: ∂L/∂y_pred_8 | B39: -0.075
A40: ∂L/∂y_pred_9 | B40: -0.01
A41: ∂L/∂y_pred_10 | B41: -0.11
A43: ∂L/∂W:
A44: ∂L/∂w1 | B44: -0.2425
A45: ∂L/∂w2 | B45: -0.70375
A46: ∂L/∂w3 | B46: -0.63875
...
